Workbook

Sheet LEMBAR KERJA
I1: LEMBAR KERJA PENGUJIAN DAN KALIBRASI
I3: AUTOCLAVE
A6: 1 | B6: PENDATAAN ADMINISTRASI
B7: Nama Faskes | F7: Klinik Pratama Ocean Dental Radio Dalam | N7: Nama Pelayanan | S7: Instalasi sterilisasi pusat
B8: Merk | F8: LOKAL | N8: Ruangan Kalibrasi | S8: STERILISASI
B9: Tipe | F9: YA28X6T/8 | N9: Tanggal Penerimaan | S9: 02 JUL 2026
B10: Nomor Seri | F10: A250705-510 | N10: Tanggal Kalibrasi | S10: 02 JUL 2026
B11: Resolusi Alat | F11: 0.1 | I11: °C | N11: Pelaksana Teknis | S11: MARSHEL ASYRAF DALTAFIKA
B12: Rentang Ukur | F12: 0.1 | I12: °C | J12: s/d | K12: 134 | L12: °C | N12: Metode Kerja | S12: RKS/MT/IK.01-010
N13: Nomor Pesanan
A15: 2 | B15: DAFTAR ALAT UKUR
B16: No. | C16: Nama Alat | I16: Merk | M16: Tipe | Q16: No. Seri | U16: Ketertelusuran
B17: 1 | C17: Electrical Safety Analyzer | I17: RIGEL | M17: 288 PLUS | Q17: 17Q-1323 | U17: LK-032-IDN
B18: 2 | C18: Thermohygrometer | I18: - | M18: HTC-1 | Q18: RKS-THG-010 | U18: LK-385-IDN
B19: 3 | C19: High Temperature Data Logger | I19: MADGETECH | M19: HiTemp140 | Q19: T53884 | U19: AC-2481
A21: 3 | B21: KONDISI LINGKUNGAN
B22: No. | C22: Parameter | K22: Awal | P22: Akhir | U22: Toleransi
B23: 1 | C23: Suhu Ruangan (°C) | K23: 24.5 | P23: 24.6 | U23: 10°C s/d 40°C
B24: =B23+1 -> 2 | C24: Kelembaban Ruangan (%RH) | K24: 55 | P24: 56 | U24: 15%RH s/d 85%RH
B25: 3 | C25: Tegangan Utama | K25: P - N | L25: : | M25: 222 | O25: Vac
A27: 4 | B27: PEMERIKSAAN FISIK DAN FUNGSI ALAT
B28: Baik | E28: = | F28: 1
B29: Tidak Baik | E29: = | F29: 0
B30: No. | C30: Parameter | H30: Batasan Pemeriksaan | U30: Hasil Pengamatan
B31: 1 | C31: Badan dan permukaan | H31: selungkup utuh, bersih, terpasang ketat satu dan lainnya dan tidak ada bekas tertimpa cairan ataupun gangguan lainnya. | U31: 1
B32: =B31+1 -> 2 | C32: Kotak Kontak Alat | H32: Periksa apakah ada gangguan pada kotak kontak (AC-Power). Gerak-gerakkan kotak kontak untuk memastikan keamanannya. Goyang-goyangkan kotak kontak untuk memastikan tidak ada baut atau mur yang longgar. | U32: 1
B33: =B32+1 -> 3 | C33: Kabel Catu Utama | H33: Periksa kabel, apakah terlihat ada kerusakan atau bagian isolasi yang terkelupas. | U33: 1
B34: =B33+1 -> 4 | C34: Sekering pengaman | H34: Periksa sekering yang terdapat pada bagian luar rangkaian, apakah nilai tahanan dan tipenya sesuai dengan spesifikasi yang tertulis pada alat. Sekering pengaman harus berfungsi baik. | U34: 1
B35: =B34+1 -> 5 | C35: Tombol, saklar dan control | H35: Sebelum mempergunakan/mengubah-ubah tombol kontrol, periksa posisi, jika terlihat tidak berada pada posisinya (periksa dengan menggunakan mode pemeriksaan standar). Bandingkan dengan posisi kontrol. Ingat pengaturan tersebut dan jangan lupa mengembalikan pada posisi awal apabila sudah selesai menggunakan alat. | U35: 1
B36: =B35+1 -> 6 | C36: Tampilan dan indikator | H36: Pastikan lampu indikator dan tampilan berfungsi seluruhnya | U36: 1
A38: 5 | B38: PENGUJIAN KESALAMATAN LISTRIK
B39: Tipe | E39: : | F39: B
B40: Kelas | E40: : | F40: I | AU40: NAMA PELAYANAN
B41: Metode | E41: : | F41: Langsung | AA41: No. | AB41: Parameter | AM41: Terukur | AU41: Pelayanan rawat jalan
B42: No. | C42: Parameter | P42: Terukur | U42: Ambang Batas | AA42: 1 | AB42: Resistansi isolasi | AM42: > | AN42: 2 | AO42: MΩ | AU42: Pelayanan UGD
B43: 1 | C43: 3 | D43: =VLOOKUP(C43,$AB$51:$AO$54,2,0) -> Resistansi pembumian Kabel dapat dilepas (DPS) | P43: 0.118 | T43: Ω | U43: ≤ | V43: =VLOOKUP(C43,$AB$51:$AO$54,13,0) -> 0.3 | X43: Ω | AA43: 2 | AB43: Arus bocor bagian yang diaplikasikan metode langsun/alternative | AU43: Bagian keuangan
B44: 2 | D44: =VLOOKUP(F39,$AB$59:$AI$61,MATCH(F40,$AB$58:$AI$58,0),0) -> Arus bocor peralatan metode Langsung kelas I tipe B | P44: 25 | T44: µA | U44: ≤ | V44: =IF(F40="I",VLOOKUP(F39,AB59:AH61,MATCH(F41,$AB$58:$AH$58,0),0),VLOOKUP(F39,AB64:AH66,MATCH(F41,$AB$58:$AH$58,0),0)) -> 500 | X44: µA | AB44: 1 | AC44: Arus bocor bagian yang diaplikasikan metode langsung tipe BF | AM44: ≤ | AN44: 5000 | AO44: µA | AU44: Ruang Rekam Medis
B45: 3 | C45: 5 | D45: =VLOOKUP(C45,$AB$44:$AO$48,2,0) -> Pengukuran arus bocor yang diaplikasikan tidak dilakukan (tidak ada bagian yang diaplikasikan) | P45: - | T45: µA | U45: ≤ | V45: =VLOOKUP(C45,$AB$44:$AO$48,13,0) -> 0 | X45: µA | AB45: 2 | AC45: Arus bocor bagian yang diaplikasikan metode langsung tipe CF | AM45: ≤ | AN45: 50 | AO45: µA | AU45: Ruang Radiologi
B46: 4 | C46: Resistansi Isolasi | P46: 100 | T46: MΩ | U46: > | V46: 2 | X46: MΩ | AB46: 3 | AC46: Arus bocor bagian yang diaplikasikan metode alternative tipe BF | AM46: ≤ | AN46: 5000 | AO46: µA | AU46: Ruang Direksi
C47: =IF(AND(F42="BF",F44="I"),2,IF(AND(F42="BF",F44="II"),11,"")) | AB47: 4 | AC47: Arus bocor bagian yang diaplikasikan metode alternative tipe CF | AM47: ≤ | AN47: 50 | AO47: µA | AU47: Ruang ICU
...

Sheet PENGOLAHAN DATA
A1: PENGOLAHAN DATA
A2: PENGUJIAN DAN KALIBRASI
A3: CENTRIFUGE
A4: A. | B4: Identitas Alat
B5: 1. | C5: ='LEMBAR KERJA'!N7 -> Nama Pelayanan | J5: : | K5: ='LEMBAR KERJA'!S7 -> Instalasi sterilisasi pusat
B6: 2. | C6: ='LEMBAR KERJA'!B8 -> Merk | J6: : | K6: ='LEMBAR KERJA'!F8 -> LOKAL
B7: 3. | C7: ='LEMBAR KERJA'!B9 -> Tipe | J7: : | K7: ='LEMBAR KERJA'!F9 -> YA28X6T/8
B8: 4. | C8: ='LEMBAR KERJA'!B10 -> Nomor Seri | J8: : | K8: ='LEMBAR KERJA'!F10 -> A250705-510
B9: 5. | C9: ='LEMBAR KERJA'!B11 -> Resolusi Alat | J9: : | K9: ='LEMBAR KERJA'!F11 -> 0.1 | L9: ='LEMBAR KERJA'!I11 -> °C
B10: 6. | C10: ='LEMBAR KERJA'!B7 -> Nama Faskes | J10: : | K10: ='LEMBAR KERJA'!F7 -> Klinik Pratama Ocean Dental Radio Dalam
B11: 7. | C11: ='LEMBAR KERJA'!N8 -> Ruangan Kalibrasi | J11: : | K11: ='LEMBAR KERJA'!S8 -> STERILISASI
B12: 8. | C12: ='LEMBAR KERJA'!N9 -> Tanggal Penerimaan | J12: : | K12: ='LEMBAR KERJA'!S9 -> 02 JUL 2026
B13: 9. | C13: ='LEMBAR KERJA'!N10 -> Tanggal Kalibrasi | J13: : | K13: ='LEMBAR KERJA'!S10 -> 02 JUL 2026
B14: 10. | C14: ='LEMBAR KERJA'!N11 -> Pelaksana Teknis | J14: : | K14: ='LEMBAR KERJA'!S11 -> MARSHEL ASYRAF DALTAFIKA
A16: B. | B16: Identitas Standar
B17: No. | C17: ='LEMBAR KERJA'!C16 -> Nama Alat | K17: ='LEMBAR KERJA'!I16 -> Merk | P17: ='LEMBAR KERJA'!M16 -> Tipe | U17: ='LEMBAR KERJA'!Q16 -> No. Seri | Z17: ='LEMBAR KERJA'!U16 -> Ketertelusuran
B18: 2 | C18: ='LEMBAR KERJA'!C17 -> Electrical Safety Analyzer | K18: ='LEMBAR KERJA'!I17 -> RIGEL | P18: ='LEMBAR KERJA'!M17 -> 288 PLUS | U18: ='LEMBAR KERJA'!Q17 -> 17Q-1323 | Z18: ='LEMBAR KERJA'!U17 -> LK-032-IDN
B19: 3 | C19: ='LEMBAR KERJA'!C18 -> Thermohygrometer | K19: ='LEMBAR KERJA'!I18 -> - | P19: ='LEMBAR KERJA'!M18 -> HTC-1 | U19: ='LEMBAR KERJA'!Q18 -> RKS-THG-010 | Z19: ='LEMBAR KERJA'!U18 -> LK-385-IDN
A21: C. | B21: Kondisi Lingkungan
B22: No. | C22: Parameter | K22: Awal | P22: Akhir | U22: Mean | X22: Koreksi Sertifikat | AA22: Ktps | AD22: Hasil Memenuhi/ Tidak
B23: 1 | C23: ='LEMBAR KERJA'!C23 -> Suhu Ruangan (°C) | K23: ='LEMBAR KERJA'!K23 -> 24.5 | N23: °C | P23: ='LEMBAR KERJA'!P23 -> 24.6 | S23: °C | U23: =AVERAGE(K23,P23) -> 24.55 | X23: =U23*'SERTIFIKAT THERMOHYGROMETER'!E19+'SERTIFIKAT THERMOHYGROMETER'!F19 -> 24.696415 | AA23: ='SERTIFIKAT THERMOHYGROMETER'!J14 -> 0.63 | AD23: =IF(AND(X23>=20,X23<=30),"Lulus","Tidak Lulus") -> Lulus
B24: =B23+1 -> 2 | C24: ='LEMBAR KERJA'!C24 -> Kelembaban Ruangan (%RH) | K24: ='LEMBAR KERJA'!K24 -> 55 | N24: %RH | P24: ='LEMBAR KERJA'!P24 -> 56 | S24: %RH | U24: =AVERAGE(K24,P24) -> 55.5 | X24: =U24*'SERTIFIKAT THERMOHYGROMETER'!N19+'SERTIFIKAT THERMOHYGROMETER'!O19 -> 55.9165 | AA24: ='SERTIFIKAT THERMOHYGROMETER'!S14 -> 2.9 | AD24: =IF(AND(X24>=35,X24<=75),"Lulus","Tidak Lulus") -> Lulus
B25: 3 | C25: ='LEMBAR KERJA'!C25 -> Tegangan Utama | H25: ='LEMBAR KERJA'!K25 -> P - N | K25: ='LEMBAR KERJA'!M25 -> 222 | U25: ='LEMBAR KERJA'!O25 -> Vac | X25: =K25 -> 222 | AA25: ='SERTIFIKAT ESA'!J28 -> -0.8 | AD25: =IF(X25>200,"Lulus","Tidak Lulus") -> Lulus
A27: D. | B27: Pemeriksaan Fisik dan Fungsi Alat
B28: No | C28: Parameter | K28: Hasil Pengamatan | P28: score | U28: kesimpulan
B29: 1 | C29: ='LEMBAR KERJA'!C31 -> Badan dan permukaan | K29: =IF('LEMBAR KERJA'!U31=1,"Baik","Tidak Baik") -> Baik | P29: =(COUNTIF(K29:N34,"baik")/(COUNTA(K29:N34))*10) -> 10 | U29: =IF(P29>=7,"Baik","Tidak Baik") -> Baik
B30: =B29+1 -> 2 | C30: ='LEMBAR KERJA'!C32 -> Kotak Kontak Alat | K30: =IF('LEMBAR KERJA'!U32=1,"Baik","Tidak Baik") -> Baik
B31: =B30+1 -> 3 | C31: ='LEMBAR KERJA'!C33 -> Kabel Catu Utama | K31: =IF('LEMBAR KERJA'!U33=1,"Baik","Tidak Baik") -> Baik
B32: =B31+1 -> 4 | C32: ='LEMBAR KERJA'!C34 -> Sekering pengaman | K32: =IF('LEMBAR KERJA'!U34=1,"Baik","Tidak Baik") -> Baik
B33: =B32+1 -> 5 | C33: ='LEMBAR KERJA'!C35 -> Tombol, saklar dan control | K33: =IF('LEMBAR KERJA'!U35=1,"Baik","Tidak Baik") -> Baik
B34: =B33+1 -> 6 | C34: ='LEMBAR KERJA'!C36 -> Tampilan dan indikator | K34: =IF('LEMBAR KERJA'!U36=1,"Baik","Tidak Baik") -> Baik
A36: E. | B36: Pengukuran Keselamatan Listrik
B37: No | C37: Parameter | J37: Hasil | N37: Koreksi Sertifikat | Q37: Ambang Batas | T37: Hasil | W37: Bobot | Z37: kesimpulan
B38: 1 | C38: ='LEMBAR KERJA'!D43 -> Resistansi pembumian Kabel dapat dilepas (DPS) | J38: ='LEMBAR KERJA'!P43 -> 0.118 | M38: Ω | N38: =J38*'SERTIFIKAT ESA'!J126+'SERTIFIKAT ESA'!J125 -> 0.085290055 | Q38: ≤ | R38: ='LEMBAR KERJA'!V43 -> 0.3 | S38: Ω | T38: =IF(N38<=R38,"Memenuhi","Tidak") -> Memenuhi | W38: =IF(COUNTIF(T38:V41,"memenuhi")<4,0,40) -> 0 | Z38: =IF((W38)<40,"Tidak Aman","Aman") -> Tidak Aman
B39: =B38+1 -> 2 | C39: ='LEMBAR KERJA'!D44 -> Arus bocor peralatan metode Langsung kelas I tipe B | J39: ='LEMBAR KERJA'!P44 -> 25 | M39: µA | N39: =J39*'SERTIFIKAT ESA'!J145+'SERTIFIKAT ESA'!J144 -> 30.5 | Q39: ≤ | R39: ='LEMBAR KERJA'!V44 -> 500 | S39: µA | T39: =IF(N39<=R39,"Memenuhi","Tidak") -> Memenuhi
B40: 3 | C40: ='LEMBAR KERJA'!D45 -> Pengukuran arus bocor yang diaplikasikan tidak dilakukan (tidak ada bagian yang diaplikasikan) | J40: ='LEMBAR KERJA'!P45 -> - | M40: µA | N40: =J40 -> - | Q40: ≤ | R40: ='LEMBAR KERJA'!V45 -> 0 | S40: µA | T40: =IF(J40<=R40,"Memenuhi","TidakMemenuhi") -> TidakMemenuhi
B41: 4 | C41: ='LEMBAR KERJA'!C46 -> Resistansi Isolasi | J41: ='LEMBAR KERJA'!P46 -> 100 | M41: MΩ | N41: =J41*'SERTIFIKAT ESA'!J184+'SERTIFIKAT ESA'!J183 -> 94.046471 | Q41: > | R41: ='LEMBAR KERJA'!V46 -> 2 | S41: MΩ | T41: =IF(J41>=R41,"Memenuhi","Tidak memenuhi") -> Memenuhi
A43: F. | B43: Pengukuran Kinerja
B44: 1. Akurasi Temperature
B45: No. | C45: Setting Alat (°C) | I45: Hasil Pengukuran (°C) | U45: Mean | X45: Stdv
...

Sheet KETIDAKPASTIAN
A1: Budget Ketidakpastian
A2: ='[1]PENGOLAHAN DATA'!A3 -> AUTOCLAVE
T3: ='[2]PENGOLAHAN DATA'!I58 -> 0
B4: n | C4: = | D4: 3 | T4: n | U4: = | V4: 3
B5: resolusi UUT | C5: = | D5: ='LEMBAR KERJA'!F11 -> 0.1 | E5: °C | T5: resolusi UUT | U5: = | V5: 0.01 | W5: detik
B7: Akurasi Temperature | T7: Titik Ukur | V7: ='[2]PENGOLAHAN DATA'!J61 -> 0 | W7: =W5 -> detik
A8: 1 | B8: Titik Ukur | D8: 121 | T8: Komponen | U8: Satuan | V8: Distribusi | W8: U | X8: Pembagi | Y8: v | Z8: u | AA8: c | AB8: (u.c) | AC8: (u.c)² | AD8: (u.c)⁴/v
B9: Komponen | C9: Satuan | D9: Distribusi | E9: U | F9: Pembagi | G9: v | H9: u | I9: c | J9: (u.c) | K9: (u.c)² | L9: (u.c)⁴/v | N9: U = stdv | T9: Pembacaan berulang | U9: detik | V9: Normal | W9: ='PENGOLAHAN DATA'!X57 -> 0 | X9: =SQRT(V4) -> 1.7320508 | Y9: =V4-1 -> 2 | Z9: =W9/X9 -> 0 | AA9: 1 | AB9: =Z9*AA9 -> 0 | AC9: =AB9^2 -> 0 | AD9: =AC9^2/Y9 -> 0
B10: Pembacaan berulang | C10: °C | D10: normal | E10: ='PENGOLAHAN DATA'!X47 -> 0.057735027 | F10: =SQRT(D4) -> 1.7320508 | G10: =D4-1 -> 2 | H10: =E10/F10 -> 0.033333333 | I10: 1 | J10: =H10*I10 -> 0.033333333 | K10: =J10^2 -> 0.0011111111 | L10: =K10^2/G10 -> 6.1728395e-07 | N10: pembagi UA = akar n | P10: Pembagi UB1 = K = 2 | T10: sertifikat Standar | U10: detik | V10: Normal | W10: ='SERTIFIKAT STOPWATCH'!K13 -> 0.029 | X10: 2 | Y10: 60 | Z10: =W10/X10 -> 0.0145 | AA10: 1 | AB10: =Z10*AA10 -> 0.0145 | AC10: =AB10^2 -> 0.00021025 | AD10: =AC10^2/Y10 -> 7.3675104e-10
B11: sertifikat Standar | C11: °C | D11: normal | E11: ='SERT. DATA LOGGER'!H15 -> 0.036 | F11: 2 | G11: 60 | H11: =E11/F11 -> 0.018 | I11: 1 | J11: =H11*I11 -> 0.018 | K11: =J11^2 -> 0.000324 | L11: =K11^2/G11 -> 1.7496e-09 | N11: pembagi UB = akar 3 | T11: Drift | U11: detik | V11: Segi 4 | W11: =10%*99.997685% -> 0.099997685 | X11: =SQRT(3) -> 1.7320508 | Y11: 50 | Z11: =W11/X11 -> 0.05773369 | AA11: 1 | AB11: =Z11*AA11 -> 0.05773369 | AC11: =AB11^2 -> 0.003333179 | AD11: =AC11^2/Y11 -> 2.2220165e-07
B12: Drift | C12: °C | D12: Segi 4 | E12: =10%*0.1 -> 0.01 | F12: =SQRT(3) -> 1.7320508 | G12: 50 | H12: =E12/F12 -> 0.0057735027 | I12: 1 | J12: =H12*I12 -> 0.0057735027 | K12: =J12^2 -> 3.3333333e-05 | L12: =K12^2/G12 -> 2.2222222e-11 | N12: v = derajat kebebasan | T12: resolusi UUT | U12: detik | V12: Segi 4 | W12: =0.5*V5 -> 0.005 | X12: =SQRT(3) -> 1.7320508 | Y12: 50 | Z12: =W12/X12 -> 0.0028867513 | AA12: 1 | AB12: =Z12*AA12 -> 0.0028867513 | AC12: =AB12^2 -> 8.3333333e-06 | AD12: =AC12^2/Y12 -> 1.3888889e-12
B13: resolusi UUT | C13: °C | D13: Segi 4 | E13: =0.5*D5 -> 0.05 | F13: =SQRT(3) -> 1.7320508 | G13: 50 | H13: =E13/F13 -> 0.028867513 | I13: 1 | J13: =H13*I13 -> 0.028867513 | K13: =J13^2 -> 0.00083333333 | L13: =K13^2/G13 -> 1.3888889e-08 | N13: u = ketidakpastian tipe A/B | T13: Human Reaction Time bias | U13: detik | V13: Segi 4 | W13: 0.00693 | X13: =SQRT(3) -> 1.7320508 | Y13: 50 | Z13: =W13/X13 -> 0.0040010374 | AA13: 1 | AB13: =Z13*AA13 -> 0.0040010374 | AC13: =AB13^2 -> 1.60083e-05 | AD13: =AC13^2/Y13 -> 5.1253134e-12
B14: Jumlah | K14: =SUM(K10:K13) -> 0.0023017778 | L14: =SUM(L10:L13) -> 6.3294466e-07 | N14: c = koef sensitivitas = 1 bila semua parameter sama | T14: Human Reaction Time Standar Deviasi | U14: detik | V14: Normal | W14: 0.03093 | X14: 1 | Y14: 50 | Z14: =W14/X14 -> 0.03093 | AA14: 1 | AB14: =Z14*AA14 -> 0.03093 | AC14: =AB14^2 -> 0.0009566649 | AD14: =AC14^2/Y14 -> 1.8304155e-08
B15: Ketidakpastian baku gabungan, Uc | K15: =SQRT(K14) -> 0.047976846 | T15: Jumlah | AC15: =SUM(AC9:AC14) -> 0.0045244355 | AD15: =SUM(AD9:AD14) -> 2.4124907e-07
B16: Derajat kebebasan efektif, V eff | K16: =K15^4/L14 -> 8.3706859 | T16: Ketidakpastian baku gabungan, Uc | AC16: =SQRT(AC15) -> 0.067263924
B17: Faktor cakupan, k-student untuk Veff dan CL 95% | K17: =TINV(0.05,K16) -> 2.3060041 | T17: Derajat kebebasan efektif, V eff | AC17: =AC16^4/AD15 -> 84.852212
B18: Ketidakpastian bentangan, U=k.Uc | K18: =K17*K15 -> 0.11063481 | L18: °C | T18: Faktor cakupan, k-student untuk Veff dan CL 95% | AC18: =TINV(0.05,AC17) -> 1.9886097
T19: Ketidakpastian bentangan, U=k.Uc | AC19: =AC18*AC16 -> 0.13376169 | AD19: =W5 -> detik
A20: 2 | B20: Titik Ukur | D20: 134
B21: Komponen | C21: Satuan | D21: Distribusi | E21: U | F21: Pembagi | G21: v | H21: u | I21: c | J21: (u.c) | K21: (u.c)² | L21: (u.c)⁴/v
B22: Pembacaan berulang | C22: °C | D22: normal | E22: ='[1]PENGOLAHAN DATA'!X48 -> 0 | F22: =SQRT(D4) -> 1.7320508 | G22: =D4-1 -> 2 | H22: =E22/F22 -> 0 | I22: 1 | J22: =H22*I22 -> 0 | K22: =J22^2 -> 0 | L22: =K22^2/G22 -> 0
B23: sertifikat Standar | C23: °C | D23: normal | E23: ='SERT. DATA LOGGER'!H15 -> 0.036 | F23: 2 | G23: 60 | H23: =E23/F23 -> 0.018 | I23: 1 | J23: =H23*I23 -> 0.018 | K23: =J23^2 -> 0.000324 | L23: =K23^2/G23 -> 1.7496e-09
B24: Drift | C24: °C | D24: Segi 4 | E24: =10%*0.1 -> 0.01 | F24: =SQRT(3) -> 1.7320508 | G24: 50 | H24: =E24/F24 -> 0.0057735027 | I24: 1 | J24: =H24*I24 -> 0.0057735027 | K24: =J24^2 -> 3.3333333e-05 | L24: =K24^2/G24 -> 2.2222222e-11
B25: resolusi UUT | C25: °C | D25: Segi 4 | E25: =0.5*D5 -> 0.05 | F25: =SQRT(3) -> 1.7320508 | G25: 50 | H25: =E25/F25 -> 0.028867513 | I25: 1 | J25: =H25*I25 -> 0.028867513 | K25: =J25^2 -> 0.00083333333 | L25: =K25^2/G25 -> 1.3888889e-08
B26: Jumlah | K26: =SUM(K22:K25) -> 0.0011906667 | L26: =SUM(L22:L25) -> 1.5660711e-08
B27: Ketidakpastian baku gabungan, Uc | K27: =SQRT(K26) -> 0.034506038
B28: Derajat kebebasan efektif, V eff | K28: =K27^4/L26 -> 90.525079
B29: Faktor cakupan, k-student untuk Veff dan CL 95% | K29: =TINV(0.05,K28) -> 1.9866745
B30: Ketidakpastian bentangan, U=k.Uc | K30: =K29*K27 -> 0.068552267 | L30: °C

Sheet LAPORAN HASIL
A1: 1 | B1: IDENTITAS ALAT
B2: Merk | G2: ='LEMBAR KERJA'!F8 -> LOKAL | O2: Resolusi | T2: ='LEMBAR KERJA'!F11 -> 0.1 | W2: °C
B3: Tipe | G3: ='LEMBAR KERJA'!F9 -> YA28X6T/8 | O3: Rentang Ukur | T3: ='LEMBAR KERJA'!F12 -> 0.1 | U3: s/d | W3: ='LEMBAR KERJA'!K12 -> 134 | X3: °C
B4: Nomor Seri | G4: ='LEMBAR KERJA'!F10 -> A250705-510
A6: 2 | B6: PELAKSANAAN KALIBRASI
B7: Nama Pelayanan | G7: ='LEMBAR KERJA'!S7 -> Instalasi sterilisasi pusat
B8: Ruangan Kalibrasi | G8: ='LEMBAR KERJA'!S8 -> STERILISASI
B9: Pelaksana Teknis | G9: ='LEMBAR KERJA'!S11 -> MARSHEL ASYRAF DALTAFIKA
A11: 3 | B11: KONDISI LINGKUNGAN
B12: Suhu | G12: ( | H12: ='PENGOLAHAN DATA'!U23 -> 24.55 | I12: ± | J12: ='PENGOLAHAN DATA'!AA23 -> 0.63 | L12: ) | M12: °C
B13: Kelembapan | G13: ( | H13: ='PENGOLAHAN DATA'!U24 -> 55.5 | I13: ± | J13: ='PENGOLAHAN DATA'!AA24 -> 2.9 | L13: ) | M13: % RH
B14: ='LEMBAR KERJA'!C25 -> Tegangan Utama | G14: P - N | I14: : | J14: ='LEMBAR KERJA'!M25 -> 222 | M14: Vac
A16: 4 | B16: DAFTAR ALAT YANG DIGUNAKAN
B17: No. | C17: Nama Alat | I17: Merk | M17: Tipe | Q17: No. Seri | U17: Ketertelusuran
B18: 1 | C18: ='LEMBAR KERJA'!C17 -> Electrical Safety Analyzer | I18: ='LEMBAR KERJA'!I17 -> RIGEL | M18: ='LEMBAR KERJA'!M17 -> 288 PLUS | Q18: ='LEMBAR KERJA'!Q17 -> 17Q-1323 | U18: ='LEMBAR KERJA'!U17 -> LK-032-IDN
B19: 2 | C19: ='LEMBAR KERJA'!C18 -> Thermohygrometer | I19: ='LEMBAR KERJA'!I18 -> - | M19: ='LEMBAR KERJA'!M18 -> HTC-1 | Q19: ='LEMBAR KERJA'!Q18 -> RKS-THG-010 | U19: ='LEMBAR KERJA'!U18 -> LK-385-IDN
B20: 3 | C20: ='LEMBAR KERJA'!C19 -> High Temperature Data Logger | I20: ='LEMBAR KERJA'!I19 -> MADGETECH | M20: ='LEMBAR KERJA'!M19 -> HiTemp140 | Q20: ='LEMBAR KERJA'!Q19 -> T53884 | U20: ='LEMBAR KERJA'!U19 -> AC-2481
A22: 5 | B22: PEMERIKSAAN KONDISI FISIK DAN FUNGSI (CEK KUALITATIF)
B23: No. | C23: Parameter | J23: Hasil
B24: 1 | C24: ='PENGOLAHAN DATA'!C29 -> Badan dan permukaan | J24: ='PENGOLAHAN DATA'!K29 -> Baik
B25: 2 | C25: ='PENGOLAHAN DATA'!C30 -> Kotak Kontak Alat | J25: ='PENGOLAHAN DATA'!K30 -> Baik
B26: 3 | C26: ='PENGOLAHAN DATA'!C31 -> Kabel Catu Utama | J26: ='PENGOLAHAN DATA'!K31 -> Baik
B27: 4 | C27: ='PENGOLAHAN DATA'!C32 -> Sekering pengaman | J27: ='PENGOLAHAN DATA'!K32 -> Baik
B28: 5 | C28: ='PENGOLAHAN DATA'!C33 -> Tombol, saklar dan control | J28: ='PENGOLAHAN DATA'!K33 -> Baik
B29: 6 | C29: ='PENGOLAHAN DATA'!C34 -> Tampilan dan indikator | J29: ='PENGOLAHAN DATA'!K34 -> Baik
A31: 6 | B31: PENGUKURAN KESELAMATAN LISTRIK
B32: No. | C32: ='[3]PENGOLAHAN DATA'!C38 -> Parameter | O32: Terukur | T32: Ambang Batas
B33: 1 | C33: ='PENGOLAHAN DATA'!C38 -> Resistansi pembumian Kabel dapat dilepas (DPS) | O33: ='PENGOLAHAN DATA'!N38 -> 0.085290055 | R33: Ω | T33: ≤ | U33: ='PENGOLAHAN DATA'!R38 -> 0.3 | X33: Ω
B34: 2 | C34: ='PENGOLAHAN DATA'!C39 -> Arus bocor peralatan metode Langsung kelas I tipe B | O34: ='PENGOLAHAN DATA'!N39 -> 30.5 | R34: µA | T34: ≤ | U34: ='PENGOLAHAN DATA'!R39 -> 500 | X34: µA
B35: 3 | C35: ='PENGOLAHAN DATA'!C40 -> Pengukuran arus bocor yang diaplikasikan tidak dilakukan (tidak ada bagian yang diaplikasikan) | O35: ='PENGOLAHAN DATA'!N40 -> - | R35: µA | T35: ≤ | U35: ='PENGOLAHAN DATA'!R40 -> 0 | X35: µA
B36: 3 | C36: ='PENGOLAHAN DATA'!C41 -> Resistansi Isolasi | O36: ='PENGOLAHAN DATA'!N41 -> 94.046471 | R36: MΩ | T36: > | U36: ='PENGOLAHAN DATA'!R41 -> 2 | X36: MΩ
A38: 7 | B38: HASIL KALIBRASI
B39: ='PENGOLAHAN DATA'!B44 -> 1. Akurasi Temperature
B40: Setting Alat | I40: Penunjukan Standar | O40: Koreksi | T40: Ambang Batas
B41: (°C) | I41: (°C) | O41: (°C)
B42: ='PENGOLAHAN DATA'!C47 -> 134 | I42: ='PENGOLAHAN DATA'!C51 -> 135.67031 | O42: ='PENGOLAHAN DATA'!F51 -> 1.6703098 | T42: ± 2 °C
B43: Ketidakpastian Pengukuran : | N43: ± | O43: =MAX('PENGOLAHAN DATA'!I51:K51) -> 0.068552267 | P43: °C
B45: ='PENGOLAHAN DATA'!B54 -> 2. Akurasi Waktu
B46: Setting Alat (Menit) | I46: Penunjukan Standar (Menit) | O46: Koreksi (Menit) | T46: Ambang Batas
B48: ='PENGOLAHAN DATA'!C57 -> 3 | I48: ='PENGOLAHAN DATA'!C61 -> 3 | O48: ='PENGOLAHAN DATA'!F61 -> 0 | T48: =IF(B42=121,'LEMBAR KERJA'!T68,'LEMBAR KERJA'!T69) -> ≥ 3 menit
...

Sheet SERT. DATA LOGGER
A1: ='[4]Sert. Tachometer'!A1:E1 -> HASIL REKALIBRASI
A4: Nama Alat | D4: : | E4: High Temperature Data Logger
A5: Merk | D5: : | E5: MADGETECH
A6: Type | D6: : | E6: HiTemp140
A7: Nomor Seri | D7: : | E7: T53884
A8: Akurasi | D8: : | E8: ±0.10°C
A9: Tgl. Kalibrasi | D9: : | E9: 17 November 22025
A10: Ketertelusuran | D10: : | E10: AC-2481
A12: Temperature
A13: No. | B13: Penunjukan Standar | D13: Pembacaan Alat | F13: Koreksi | H13: Uncertainty
A14: 1 | B14: 30 | C14: °C | D14: 29.995 | E14: =$C$14 -> °C | F14: =B14-D14 -> 0.005 | G14: =$C$14 -> °C | H14: 0.039
A15: 2 | B15: 140.03 | C15: =C14 -> °C | D15: 140.034 | E15: =$C$14 -> °C | F15: =B15-D15 -> -0.004 | G15: =$C$14 -> °C | H15: 0.036
B17: SUMMARY OUTPUT
B19: Regression Statistics
B20: Multiple R | C20: 1
B21: R Square | C21: 1
B22: Adjusted R Square | C22: 65535
B23: Standard Error | C23: 0
B24: Observations | C24: 2
B26: ANOVA
C27: df | D27: SS | E27: MS | F27: F | G27: Significance F
B28: Regression | C28: 1 | D28: 6054.2908 | E28: 6054.2908 | F28: #NUM! | G28: #NUM!
B29: Residual | C29: 0 | D29: 0 | E29: 65535
B30: Total | C30: 1 | D30: 6054.2908
C32: Coefficients | D32: Standard Error | E32: t Stat | F32: P-value | G32: Lower 95% | H32: Upper 95% | I32: Lower 95.0% | J32: Upper 95.0%
B33: Intercept | C33: -0.0074538762 | D33: 0 | E33: 65535 | F33: #NUM! | G33: #VALUE! | H33: #VALUE! | I33: -0.0074538762 | J33: -0.0074538762
B34: X Variable 1 | C34: 1.0000818 | D34: 0 | E34: 65535 | F34: #NUM! | G34: 1.0000818 | H34: 1.0000818 | I34: 1.0000818 | J34: 1.0000818

Sheet SERTIFIKAT ESA
A2: Nama Alat | B2: : | C2: Electrical Safety Analyzer
A3: Merk | B3: : | C3: RIGEL
A4: Model/Type | B4: : | C4: 288 PLUS
A5: Nomor Seri | B5: : | C5: 17Q-1323
A6: Tanggal Kalibrasi | B6: : | C6: 11-01-2024
A7: Ketelusuran | B7: : | C7: LK-032-IDN
A8: No. Sertifikat | B8: : | C8: S. 23 018 845
C10: 1. Earth Bond
C11: No | D11: Range | F11: Penunjukan Standar (Ω) | H11: Pembacaan Alat (Ω) | J11: Koreksi | K11: Ketidakpastian
C12: 1 | D12: 5 | E12: Ω | F12: 0.01 | G12: =E12 -> Ω | H12: 0.009 | I12: =E12 -> Ω | J12: =F12-H12 -> 0.001 | K12: 1.8 | L12: % of reading
C13: 2 | E13: Ω | F13: 0.1 | G13: =E13 -> Ω | H13: 0.11 | I13: =E13 -> Ω | J13: =F13-H13 -> -0.01
C14: 3 | E14: Ω | F14: 1 | G14: =E14 -> Ω | H14: 1.08 | I14: =E14 -> Ω | J14: =F14-H14 -> -0.08
D16: slope b = | E16: {=LINEST(F12:F14,H12:H14,1,1)} -> 0.92576194 | F16: 3.8128973e-06 | G16: = intersept : a
D17: standard deviation of slope : | E17: 0.0029718593 | F17: 0.001862719 | G17: = standard deviation of intercept
D18: Coefficient of determination : r2 | E18: 0.99998969 | F18: 0.0024853357 | G18: = standard error of regression
D19: Fisher F-statistics | E19: 97038.068 | F19: 1 | G19: = Degree of the regression
D20: Sum of square due to regression | E20: 0.59939382 | F20: 6.1768937e-06 | G20: = sum of square due to residual
C23: 2. Earth Leakage
C24: No | D24: Range ( µA) | F24: Pembacaan Alat ( µA) | H24: Penunjukan Standar ( µA) | J24: Koreksi | K24: Ketidakpastian
C25: 1 | D25: 10000 | F25: 50 | H25: 49.8 | J25: =H25-F25 -> -0.2 | K25: 2.9 | L25: % of reading
C26: 2 | F26: 100 | H26: 98.9 | J26: =H26-F26 -> -1.1
C27: 3 | F27: 200 | H27: 199 | J27: =H27-F27 -> -1
C28: 4 | F28: 500 | H28: 499.2 | J28: =H28-F28 -> -0.8
C29: 5 | F29: 1000 | H29: 999.7 | J29: =H29-F29 -> -0.3
C30: 6 | F30: 2000 | H30: 2000.6 | J30: =H30-F30 -> 0.6
C31: 7 | F31: 4000 | H31: 4002.5 | J31: =H31-F31 -> 2.5
C32: 8 | F32: 6000 | H32: 6004.3 | J32: =H32-F32 -> 4.3
C33: 9 | F33: 8000 | H33: 8006.2 | J33: =H33-F33 -> 6.2
C34: 10 | F34: 9500 | H34: 9507.6 | J34: =H34-F34 -> 7.6
D36: slope b = | E36: {=LINEST(H25:H34,F25:F34,1,1)} -> 1.0009003 | F36: -1.0424348 | G36: = intersept : a
D37: standard deviation of slope : | E37: 2.9457041e-05 | F37: 0.13548718 | G37: = standard deviation of intercept
D38: Coefficient of determination : r2 | E38: 0.99999999 | F38: 0.31350686 | G38: = standard error of regression
D39: Fisher F-statistics | E39: 1.1545251e+09 | F39: 8 | G39: = Degree of the regression
D40: Sum of square due to regression | E40: 1.134743e+08 | F40: 0.78629243 | G40: = sum of square due to residual
C43: 3. Direct Equipment Leakage
C44: No | D44: Range ( µA) | F44: Pembacaan Alat ( µA) | H44: Penunjukan Standar ( µA) | J44: Koreksi | K44: Ketidakpastian
C45: 1 | D45: 10000 | F45: 50 | H45: 53.4 | J45: =H45-F45 -> 3.4 | K45: 2.9 | L45: % of reading
C46: 2 | F46: 100 | H46: 103.6 | J46: =H46-F46 -> 3.6
C47: 3 | F47: 200 | H47: 203.9 | J47: =H47-F47 -> 3.9
C48: 4 | F48: 500 | H48: 505.1 | J48: =H48-F48 -> 5.1
...

Sheet SERTIFIKAT THERMOHYGROMETER
A1: HASIL KALIBRASI
A4: Nama Alat | B4: : | C4: Thermohygrometer
A5: Merk | B5: : | C5: -
A6: Type | B6: : | C6: HTC-1
A7: Nomor Seri | B7: : | C7: RKS-THG-010
A8: Tanggal Kalibrasi | B8: : | C8: 18-07-2023
A9: No. Sertifikat | B9: : | C9: 2023072286
A10: Ketelusuran | B10: : | C10: -
C12: SUHU | L12: KELEMBABAN
C13: No | D13: Penunjukan Standar | F13: Penunjukan Alat | H13: Koreksi | J13: uncert | L13: No | M13: Penunjukan Standar | O13: Penunjukan Alat | Q13: Koreksi | S13: uncert
C14: 1 | D14: 20.12 | E14: °C | F14: 20 | G14: °C | H14: 0.1 | I14: °C | J14: 0.63 | L14: 1 | M14: 40.7 | N14: %RH | O14: 40 | P14: %RH | Q14: -2.4 | R14: %RH | S14: 2.9
C15: 2 | D15: 25.17 | E15: °C | F15: 25 | G15: °C | H15: 0.2 | I15: °C | L15: 2 | M15: 50.3 | N15: %RH | O15: 50 | P15: %RH | Q15: 3.3 | R15: %RH
C16: 3 | D16: 30.22 | E16: °C | F16: 30.1 | G16: °C | H16: 0.2 | I16: °C | L16: 3 | M16: 60.7 | N16: %RH | O16: 60 | P16: %RH | Q16: 3.8 | R16: %RH
C17: 4 | D17: 35.27 | E17: °C | F17: 35 | G17: °C | H17: 0.2 | I17: °C | L17: 4 | M17: 70 | N17: %RH | O17: 70 | P17: %RH | Q17: 0 | R17: %RH
D19: slope b = | E19: {=LINEST(D14:D17,F14:F17,1,1)} -> 1.0079278 | F19: -0.048213055 | G19: = intersept : a | M19: slope b = | N19: {=LINEST(M14:M17,O14:O17,1,1)} -> 0.983 | O19: 1.36 | P19: = intersept : a
D20: standard deviation of slope : | E20: 0.0053228071 | F20: 0.14951333 | G20: = standard deviation of intercept | M20: standard deviation of slope : | N20: 0.014247807 | O20: 0.79965618 | P20: = standard deviation of intercept
D21: Coefficient of determination : r2 | E21: 0.99994423 | F21: 0.059631477 | G21: = standard error of regression | M21: Coefficient of determination : r2 | N21: 0.99958001 | O21: 0.31859065 | P21: = standard error of regression
D22: Fisher F-statistics | E22: 35857.286 | F22: 2 | G22: = Degree of the regression | M22: Fisher F-statistics | N22: 4760.0443 | O22: 2 | P22: = Degree of the regression
D23: Sum of square due to regression | E23: 127.50539 | F23: 0.007111826 | G23: = sum of square due to residual | M23: Sum of square due to regression | N23: 483.1445 | O23: 0.203 | P23: = sum of square due to residual

Sheet SERTIFIKAT STOPWATCH
A1: HASIL KALIBRASI
A4: Nama Alat | B4: : | C4: Stopwatch
A5: Merk | B5: : | C5: CITIZEN
A6: Type | B6: : | C6: 8RDA55
A7: Nomor Seri | B7: : | C7: Z0775G
A8: Tanggal Kalibrasi | B8: : | C8: 13-03-2026
A9: No. Sertifikat | B9: : | C9: S. 26 004 123
A10: Ketelusuran | B10: : | C10: LK-032-IDN
D12: No | E12: Penunjukan Standar | G12: Penunjukan Alat | I12: Koreksi | K12: Ketidakpastian
D13: 1 | E13: =G13+I13 -> 10.037 | F13: s | G13: 10 | H13: s | I13: 0.037 | J13: =F13 -> s | K13: 0.029
D14: 2 | E14: =G14+I14 -> 20.044 | F14: s | G14: 20 | H14: s | I14: 0.044 | J14: =F14 -> s
D15: 3 | E15: =G15+I15 -> 30.039 | F15: s | G15: 30 | H15: s | I15: 0.039 | J15: =F15 -> s
D16: 4 | E16: =G16+I16 -> 40.032 | F16: s | G16: 40 | H16: s | I16: 0.032 | J16: =F16 -> s
D17: 5 | E17: =G17+I17 -> 50.011 | F17: s | G17: 50 | H17: s | I17: 0.011 | J17: =F17 -> s
D18: 6 | E18: =G18+I18 -> 59.981 | F18: s | G18: 60 | H18: s | I18: -0.019 | J18: =F18 -> s
D19: 7 | E19: =G19+I19 -> 299.99 | F19: s | G19: 300 | H19: s | I19: -0.01 | J19: s
D20: 8 | E20: =G20+I20 -> 600.005 | F20: s | G20: 600 | H20: s | I20: 0.005 | J20: s
F22: SUMMARY OUTPUT
F24: Regression Statistics
F25: Multiple R | G25: 0.99999999
F26: R Square | G26: 0.99999999
F27: Adjusted R Square | G27: 0.99999999
F28: Standard Error | G28: 0.023038087
F29: Observations | G29: 8
F31: ANOVA
G32: df | H32: SS | I32: MS | J32: F | K32: Significance F
F33: Regression | G33: 1 | H33: 305087.5 | I33: 305087.5 | J33: 5.748196e+08 | K33: 3.5539315e-25
F34: Residual | G34: 6 | H34: 0.0031845208 | I34: 0.00053075347
F35: Total | G35: 7 | H35: 305087.5
G37: Coefficients | H37: Standard Error | I37: t Stat | J37: P-value | K37: Lower 95% | L37: Upper 95% | M37: Lower 95.0% | N37: Upper 95.0%
F38: Intercept | G38: -0.02473162 | H38: 0.0099923776 | I38: -2.4750486 | J38: 0.048127191 | K38: -0.049182087 | L38: -0.00028115303 | M38: -0.049182087 | N38: -0.00028115303
F39: X Variable 1 | G39: 1.000053 | H39: 4.1711637e-05 | I39: 23975.396 | J39: 3.5539315e-25 | K39: 0.99995095 | L39: 1.0001551 | M39: 0.99995095 | N39: 1.0001551
